Workbook
Name _W012133: W!$A$1:$B$865
Name WHStest_6: W!#REF!

Sheet Ваши решения
G2: Управленческий отчёт
B3: =W!A861 -> This is a history quarter | V3: Код: | W3: =W!A6 -> 26C1
B4: =W!A862 -> 0
B5: =W!A863 -> 0 | H5: Компания | L5: =W!$A2 -> 0 | N5: Группа | O5: =W!$A1 -> 0
B6: =W!A864 -> 0
C9: ПРОВЕРЬТЕ … | H9: Решения | O9: Год | P9: =W!$A4 -> 2025 | R9: Кв | S9: =W!$A5 -> 2
E12: Имидж | F12: Продукт | G12: 1 | H12: Продукт | I12: 2 | J12: Продукт | K12: 3 | P12: Через | T12: Вознагр. | W12: Комис.
C13: Реклама (тыс. ерз.): | M13: Агенты и дистрибьюторы: | P13: квартал | T13: (тыс. ерз.) | W13: %
D14: ЕАЭС | E14: =W!A7 -> 15 | F14: =W!A11 -> 10 | H14: =W!A14 -> 10 | J14: =W!A17 -> 10 | M14: Агенты в ЕАЭС | P14: =W!A61 -> 3 | Q14: =W!B61 -> 0 | T14: =W!A62 -> 9 | U14: =W!B62 -> 0 | W14: =W!A63 -> 7
D15: АСЕАН | E15: =W!A8 -> 0 | F15: =W!A12 -> 0 | H15: =W!A15 -> 0 | J15: =W!A18 -> 0 | M15: Дистрибьюторы АСЕАН | P15: =W!A64 -> 0 | Q15: =W!B64 -> 0 | T15: =W!A65 -> 0 | U15: =W!B65 -> * | W15: =W!A66 -> 0
D16: Интернет | E16: =W!A9 -> 0 | F16: =W!A13 -> 0 | H16: =W!A16 -> 0 | J16: =W!A19 -> 0 | M16: Интернет-агент | T16: =W!A68 -> 0 | U16: =W!B68 -> * | W16: =W!A69 -> 0
C18: Цены (ерз.): | M18: Операционная деятельность:
D19: ЕАЭС | F19: =W!A21 -> 285 | G19: =W!B21 -> 0 | H19: =W!A24 -> 450 | I19: =W!B24 -> 0 | J19: =W!A27 -> 680 | K19: =W!B27 -> 0 | M19: Заказано сырья (тыс.шт.) | O19: СПОТ | P19: =W!A57 -> 0 | S19: 3 мес. | T19: =W!A58 -> 2 | V19: 6 мес. | W19: =W!A59 -> 0
D20: АСЕАН | F20: =W!A22 -> 0 | G20: =W!B22 -> 0 | H20: =W!A25 -> 0 | I20: =W!B25 -> 0 | J20: =W!A28 -> 0 | K20: =W!B28 -> 0 | M20: Время на ТО 1 станка (час) | P20: =W!A75 -> 15 | S20: Кол-во рабочих смен | W20: =W!A76 -> 2
D21: Интернет | F21: =W!A23 -> 0 | G21: =W!B23 -> 0 | H21: =W!A26 -> 0 | I21: =W!B26 -> 0 | J21: =W!A29 -> 0 | K21: =W!B29 -> 0 | M21: Кол-во Интернет-портов | P21: =W!A77 -> 0 | S21: Развитие сайта (тыс. ерз.) | W21: =W!A78 -> 0
C23: Количество произведённой и отгруженной продукции (шт.): | M23: Управление персоналом
C24: Агенты в ЕАЭС | F24: =W!A31 -> 750 | G24: =W!B31 -> 0 | H24: =W!A34 -> 500 | I24: =W!B34 -> 0 | J24: =W!A37 -> 335 | K24: =W!B37 -> 0 | M24: Сборщики: Нанять (+) / Увол. (-) | P24: =W!A81 -> 0 | Q24: =W!B81 -> 0 | S24: Повыш. Квалификации | W24: =W!A82 -> 3 | X24: =W!B82 -> 0
C25: Дистрибьюторы АСЕАН | F25: =W!A32 -> 0 | G25: =W!B32 -> 0 | H25: =W!A35 -> 0 | I25: =W!B35 -> 0 | J25: =W!A38 -> 0 | K25: =W!B38 -> 0 | M25: Часовая зарплата сборщика | P25: =W!A83/100 -> 10 | Q25: =W!B83 -> 0
C26: Интернет-агент | F26: =W!A33 -> 0 | G26: =W!B33 -> 0 | H26: =W!A36 -> 0 | I26: =W!B36 -> 0 | J26: =W!A39 -> 0 | K26: =W!B39 -> 0 | M26: Управленческий бюджет (тыс.ерз.) | P26: =W!A85 -> 60 | Q26: =W!B85 -> 0 | S26: Тренинги (дней) | W26: =W!A86 -> 2 | X26: =W!B86 -> 0
D27: (доставлен не полностью, если пометка *)
C28: Качество продукции: | M28: Финансы:
C29: Внедрить новые разработки (1;0) | F29: =W!A41 -> 0 | H29: =W!A42 -> 0 | J29: =W!A43 -> 0 | M29: Эмиссия/Выкуп акций | P29: =W!A91 -> 0 | Q29: =W!B91 -> 0 | S29: Дивиденды (в %) | W29: =W!A92 -> 0 | X29: =W!B92 -> 0
C30: Вложения в НИОКР (тыс.ерз.) | F30: =W!A44 -> 25 | H30: =W!A45 -> 20 | J30: =W!A46 -> 15 | M30: Срочные кредиты (тыс. ерз.) | P30: =W!A93 -> 0 | Q30: =W!B93 -> 0 | S30: Срочный депозит (т. ерз.) | W30: =W!A94 -> -500 | X30: =W!B94 -> 0
C31: Время сборки (минуты) | F31: =W!A47 -> 115 | H31: =W!A48 -> 165 | J31: =W!A49 -> 325 | M31: Покупка станков (шт.) | P31: =W!A73 -> 2 | Q31: =W!B73 -> 0 | S31: Продажа станков (шт.) | W31: =W!A74 -> 0 | X31: =W!B74 -> 0
C32: Премиальные материалы (%) | F32: =W!A51 -> 0 | G32: =W!B51 -> 0 | H32: =W!A52 -> 0 | I32: =W!B52 -> 0 | J32: =W!A53 -> 0 | K32: =W!B53 -> 0 | M32: Расширение цеха (кв. м.) | P32: =W!A72 -> 0 | Q32: =W!B72 -> 0 | S32: Страховой план | W32: =W!A99 -> 1
C34: Аутсорсинг: | M34: Информация:
C35: Заказанные полуфабрикаты (шт.) | F35: =W!A54 -> 0 | G35: =W!B54 -> 0 | H35: =W!A55 -> 0 | I35: =W!B55 -> 0 | J35: =W!A56 -> 0 | K35: =W!B56 -> 0 | M35: О долях рынка | P35: =W!A97 -> 0 | S35: О дея-ти конкурентов | W35: =W!A98 -> 1
B37: The Global Management Challenge is a business simulation designed by Edit Systems Ltd. (www.edit515.co.uk) and organised by SDG S.A. (www.worldgmc.com) World Copyright © 2013 - EDIT 515 Ltd, UK and SDG - Simuladores e Modelos de Gestão, S.A. Адаптировано Президентской Академией (РАНХиГС) для использования в России и СНГ

Sheet Ресурсы и продукты
D1: Группа | E1: =W!A1 -> 0 | F1: Компания | H1: =W!A2 -> 0 | M1: Ресурсы и продукты | T1: Год | U1: =W!A4 -> 2025 | W1: Кв | X1: =W!A5 -> 2
C4: Использование материальных ресурсов | K4: Человеческие ресурсы: | S4: Движение товара: | U4: Продукт 1 | W4: Продукт 2 | Y4: Продукт 3
S5: Количество продукции:
C6: Пространство: | G6: Кв. м. | K6: Движение персонала: | N6: Сборщики | O6: Механики | S6: Запланировано | U6: =W!A108 -> 750 | W6: =W!A109 -> 500 | Y6: =W!A110 -> 335
C7: Земля в собственности | G7: =W!A281 -> 1000 | K7: На начало прош. квартала | N7: =W!A191 -> 11 | O7: =W!A192 -> 0 | S7: Произведено | U7: =W!A111 -> 768 | W7: =W!A112 -> 512 | Y7: =W!A113 -> 343
C8: Инфраструктурные объекты | G8: =0.2*G7 -> 200 | K8: рекрутировано | N8: =W!A193 -> 0 | O8: =W!A194 -> 16 | S8: Брак | U8: =W!A114 -> 18 | W8: =W!A115 -> 12 | Y8: =W!A116 -> 8
C9: Располагаемая площадь | G9: =G7-G8-G10 -> 300 | K9: Обучено | N9: =W!A82 -> 3 | S9: Потеряно/уничтожено | U9: =W!A117 -> 0 | V9: =W!B117 -> 0 | W9: =W!A118 -> 0 | X9: =W!B118 -> 0 | Y9: =W!A119 -> 0 | Z9: =W!B119 -> 0
C10: Размер цеха в след. квартале | G10: =W!A284 -> 500 | K10: Уволено | N10: =W!A195 -> 0 | O10: =W!A196 -> 0
C11: Инфраструктура цеха | G11: =0.25*G10 -> 125 | K11: Увол. по собств. желанию | N11: =N7+N8+N9-N10-N12 -> 0 | O11: =O7+O8+O9-O10-O12 -> 1 | S11: Отгружено:
C12: Изготовление деталей | G12: =W!A285 -> 100 | K12: Доступно на нач.след.кв. | N12: =W!A197 -> 14 | O12: =W!A198 -> 15 | S12: Агентам в ЕАЭС | U12: =W!A121 -> 750 | W12: =W!A124 -> 500 | Y12: =W!A127 -> 335
C13: Сборка | G13: =W!A286 -> 140 | S13: Дистрибьюторам АСЕАН | U13: =W!A122 -> 0 | W13: =W!A125 -> 0 | Y13: =W!A128 -> 0
C14: Складирование | G14: =W!A287 -> 0 | S14: Интернет-агенту | U14: =W!A123 -> 0 | W14: =W!A126 -> 0 | Y14: =W!A129 -> 0
C15: Свободная площадь (+/-): | G15: =G10-SUM(G11:G14) -> 135 | K15: Сборщики: | O15: Часы
K16: Доступно часов работы в прош.кв | O16: =W!A305 -> 6336 | S16: Заказы из:
C17: Станки: | G17: Количество | K17: Общее время отсутствия/болезни | O17: =W!A306 -> 1 | P17: =W!B307 -> 0 | S17: ЕАЭС | U17: =W!A131 -> 594 | W17: =W!A134 -> 375 | Y17: =W!A137 -> 210
C18: Выведено из эксплуатации | G18: =W!A291 -> 0 | K18: Фактически отработано часов | O18: =W!A307 -> 4737 | S18: АСЕАН | U18: =W!A132 -> 0 | W18: =W!A135 -> 0 | Y18: =W!A138 -> 0
C19: Использовалось в прош. квартале | G19: =W!A292 -> 2 | O19: Недели | S19: Интернет | U19: =W!A133 -> 0 | W19: =W!A136 -> 0 | Y19: =W!A139 -> 0
C20: Куплено и установлено | G20: =W!A293 -> 2 | K20: Уведомл. о забастовках в след.кв-ле | O20: =W!A308 -> 0
C21: Доступно для след. квартала | G21: =W!A294 -> 4 | S21: Продано в:
S22: ЕАЭС | U22: =W!A141 -> 594 | W22: =W!A144 -> 375 | Y22: =W!A147 -> 210
C23: Доступных часов работы в прош.кв. | G23: =W!A301 -> 2136 | S23: АСЕАН | U23: =W!A142 -> 0 | W23: =W!A145 -> 0 | Y23: =W!A148 -> 0
C24: Часов простоя станков | G24: =W!A302 -> 21 | H24: =W!B302 -> 0 | S24: Интернет | U24: =W!A143 -> 0 | W24: =W!A146 -> 0 | Y24: =W!A149 -> 0
C25: Отработано часов в прош. кв. | G25: =W!A303 -> 2113 | K25: Движение агентов: | M25: ЕАЭС | N25: АСЕАН | O25: Интернет
C26: Часы запланированного техосмотра | G26: =G19*W!A75-G24 -> 9 | K26: Доступные в прош.кв. | M26: =W!A321 -> 2 | N26: =W!A322 -> 0 | O26: =IF(W!A327>0,1,0) -> 0 | S26: Долги по поставкам:
C27: Средняя эффективность станка % | G27: =W!A304 -> 99.0 | K27: Покинули компанию | M27: =W!A323 -> 0 | N27: =W!A324 -> 0 | S27: ЕАЭС | U27: =W!A151 -> 0 | W27: =W!A154 -> 0 | Y27: =W!A157 -> 0
K28: Уволены в прошл.кв. | M28: =MAX(M26-M27-M30,0) -> 0 | N28: =MAX(N26-N27-N30,0) -> 0 | O28: =O26-O30 -> 0 | S28: АСЕАН | U28: =W!A152 -> 0 | W28: =W!A155 -> 0 | Y28: =W!A158 -> 0
C29: Материалы: | K29: Нанятые для след.кв. | M29: =MAX(M30-M26+M27,0) -> 1 | N29: =MAX(N30-N26+N27,0) -> 0 | O29: =O30-O26 -> 0
C30: Остатки сырья на начало периода | G30: =W!A311 -> 3000 | K30: Доступно в след.кв. | M30: =W!A325 -> 3 | N30: =W!A326 -> 0 | O30: =IF(W!A328>0,1,0) -> 0 | S30: Склады:
C31: Закуплено сырья в прош. кв. | G31: =1000*W!A57+W!A312 -> 0 | S31: ЕАЭС | U31: =W!A161 -> 156 | W31: =W!A164 -> 125 | Y31: =W!A167 -> 125
C32: Закуплено автоматически | G32: =W!A313 -> 0 | S32: АСЕАН | U32: =W!A162 -> 0 | W32: =W!A165 -> 0 | Y32: =W!A168 -> 0
C33: Потеряно/уничтожено | G33: =W!A314 -> 0 | H33: =W!B313 -> 0 | S33: Интернет | U33: =W!A163 -> 0 | W33: =W!A166 -> 0 | Y33: =W!A169 -> 0
C34: Использовано сырья | G34: =W!A315 -> 2821
C35: Остатки сырья на конец прош. кв. | G35: =W!A316 -> 179 | K35: Траспорт: | M35: ЕАЭС | N35: АСЕАН | O35: Интернет
C36: Будет доставлено в след. квартале: | K36: Сред.километраж | M36: =W!A295 -> 1434 | N36: =W!A297 -> 0 | O36: =W!A299 -> 0 | S36: Обслужено по | U36: =W!A171 -> 0 | V36: =W!B171 -> 0 | W36: =W!A172 -> 0 | X36: =W!B172 -> 0 | Y36: =W!A173 -> 0 | Z36: =W!B173 -> 0
C37: Купленного в прошлом квартале | G37: =1000*W!A58 -> 2000 | K37: Кол-во отгрузок | M37: =W!A296 -> 7 | N37: =W!A298 -> 0 | O37: =W!A300 -> 0 | S37: гарантии
C38: Купленного 2 квартала назад | G38: =W!A317 -> 0
C39: Будет доставлено через один квартал: | G39: =1000*W!A59 -> 0 | S39: Новые разработки | U39: =W!A177 -> Minor | W39: =W!A178 -> None | Y39: =W!A179 -> None
C41: Интернет-статистика: | S41: Полуфабрикаты:
C42: Количество действующих портов | G42: =W!A318 -> 0 | K42: Углеродный след (CO2e): | N42: Тонны | S42: Использовано в сборке | U42: =W!A181 -> 0 | W42: =W!A182 -> 0 | Y42: =W!A183 -> 0
C43: Успешные посещения сайта | G43: =W!A319 -> 0 | K43: Отопление и освещение цеха | N43: =0.00019*50*G10 -> 4.75 | S43: Заказано в прошл. кв. | U43: =W!A54 -> 0 | W43: =W!A55 -> 0 | Y43: =W!A56 -> 0
...

Sheet Финансовая отчетность
D1: Группа | E1: =W!A1 -> 0 | F1: Компания | I1: =W!A2 -> 0 | M1: Финансовая отчётность | U1: Год | V1: =W!A4 -> 2025 | W1: Кв | X1: =W!A5 -> 2
C4: ФИНАНСОВАЯ ОТЧЁТНОСТЬ | F4: (ерз. )
U5: ОТЧЁТ О ДВИЖЕНИИ
C6: НАКЛАДНЫЕ РАСХОДЫ | I6: ОТЧЁТ О ПРИБЫЛЯХ И УБЫТКАХ | O6: БАЛАНС КОМПАНИИ | U6: ДЕНЕЖНЫХ СРЕДСТВ
C8: Реклама | F8: =W!A201 -> 45000 | I8: Выручка от реализации | L8: =W!A241 -> 483480 | O8: Внеоборотные активы: | U8: Операционная деятельность:
C9: Интернет-агент | F9: =W!A202 -> 0 | O9: Стоимость земли | R9: =W!A261 -> 50000 | U9: Поступления от продаж | X9: =W!A221 -> 183382
C10: Интернет-провайдер | F10: =W!A203 -> 0 | I10: Складские ост. на начало кв. | L10: =W!A242 -> 94909 | O10: Стоимость построек | R10: =W!A262 -> 250000 | U10: Страховые поступления | X10: =W!A222 -> 0
C11: Агенты и дистрибьюторы | F11: =W!A204 -> 59158 | I11: Закупленные полуфабрикаты | L11: =W!A243 -> 0 | O11: Стоимость оборудования | R11: =W!A263 -> 1155376 | U11: Платежи по операц. деят-ти | X11: =W!A223 -> 561735
C12: Офис продаж | F12: =W!A205 -> 4834 | I12: Закупленное сырье | L12: =W!A244 -> 71444 | O12: Всего внеоборотных активов | R12: =SUM(R9:R11) -> 1455376 | U12: Уплаченные налоги | X12: =W!A224 -> 0
C13: Гарантийное обслуживание | F13: =W!A206 -> 0 | I13: Затраты на эксплуатацию станков | L13: =W!A245 -> 50489 | U13: Ден. поток по операц. деят-ти | X13: =X9+X10-X11-X12 -> -378353
C14: Исследования и разработки | F14: =W!A207 -> 60000 | I14: Зарплаты механиков | L14: =W!A246 -> 86807 | O14: Оборотные активы:
C15: Развитие веб-сайта | F15: =W!A208 -> 0 | I15: Зарплаты сборщиков | L15: =W!A247 -> 59680 | O15: Ст-ть товарных запасов | R15: =W!A265 -> 67194 | U15: Инвестиционная деятельность:
C16: Отдел персонала | F16: =W!A209 -> 43500 | I16: Контроль качества | L16: =W!A248 -> 1623 | O16: Ст-ть запасов полуфабр. | R16: =W!A266 -> 0 | U16: Полученный процент | X16: =W!A225 -> 11875
C17: Техобслуживание оборудов. | F17: =W!A210 -> 2550 | I17: Аренда транспорта | L17: =W!A249 -> 18200 | O17: Стоимость запасов сырья | R17: =W!A267 -> 71573 | U17: Активов продано | X17: =W!A226 -> 0
C18: Складирование и закупка | F18: =W!A211 -> 8207 | I18: Складские ост. на конец кв. | L18: =W!A250 -> 138767 | O18: Дебиторская задолженность | R18: =W!A268 -> 300098 | U18: Активов куплено | X18: =W!A227 -> 600000
C19: Расходы на маркет.исслед. | F19: =W!A212 -> 7500 | I19: Затраты на пр-во и реал. пр. | L19: =W!A251 -> 244385 | O19: Денежные ср-ва и их экв-ты | R19: =W!A269 -> 1900000 | U19: Ден. поток по инвест. деят-ти | X19: =X16+X17-X18 -> -588125
C20: Кредитный контроль | F20: =W!A213 -> 1179 | I20: Валовая прибыль/убыток | L20: =W!A252 -> 239095 | O20: Итого оборотные активы | R20: =SUM(R15:R19) -> 2338865
C21: Страховая премия | F21: =W!A214 -> 5879 | I21: Накладные расходы | L21: =W!A217 -> 308359 | O21: Итого активы | R21: =R12+R20 -> 3794241 | U21: Финансовая деятельность:
C22: Управленческий бюджет | F22: =W!A215 -> 60000 | I22: Страховые поступления | L22: =W!A222 -> 0 | U22: Акций выпущено | X22: =W!A228 -> 0
C23: Прочие издержки | F23: =W!A216 -> 10552 | I23: Амортизация | L23: =W!A254 -> 29624 | O23: Обязательства: | U23: Акций выкуплено | X23: =W!A229 -> 0
C24: Итого накладные расходы | F24: =W!A217 -> 308359 | I24: Операц. прибыль/убыток | L24: =L20-L21+L22-L23 -> -98888 | O24: Задолженность по налогам | R24: =W!A271 -> 0 | U24: Дивиденды | X24: =W!A230 -> 0
I25: Полученный процент | L25: =W!A225 -> 11875 | O25: Кредиторская задолженность | R25: =W!A272 -> 109679 | U25: Доп. срочные кредиты | X25: =W!A231 -> 0
C26: Налогообл. прибыль/убыток (накопл.): | I26: Уплаченный процент | L26: =W!A232 -> 16545 | O26: Банковский овердрафт | R26: =W!A273 -> 1035760 | U26: Уплаченный процент | X26: =W!A232 -> 16545
C27: Прибыль до налогообложения | F27: =L27 -> -103558 | I27: Прибыль/убыток до налогообл. | L27: =L24+L25-L26 -> -103558 | O27: Краткосрочные обязательства | R27: =SUM(R24:R26) -> 1145439 | U27: Ден. поток по фин. деят-ти | X27: =X22-X23-X24+X25-X26 -> -16545
C28: Налогообл. приб. в прош. кв. | F28: =W!A240 -> -247640 | I28: Налоги начисленные | L28: =W!A255 -> 0 | O28: Срочные кредиты | R28: =W!A274 -> 0
C29: Налогооблагаемая прибыль | F29: =W!A257 -> -351198 | I29: Прибыль за отчётный период | L29: =W!A256 -> -103558 | U29: Чистый денежный поток | X29: =W!A233 -> -983023
I30: Прибыль на акцию (копеек) | L30: =IF(R33>0,100*L29/R33,0) -> -3.4519333 | O30: Чистые активы | R30: =R21-R27-R28 -> 2648802 | U30: Нал. ср-ва в позапрош. кв. | X30: =W!A234 -> 1847263
U31: Наличные средства | X31: =R19-R26 -> 864240
I32: Дивиденды | L32: =W!A230 -> 0 | O32: Собственный капитал: | U32: (включая срочный депозит - | X32: =W!A270 -> 1900000 | Y32: )
C33: Иски к страховой компании | F33: =W!A219 -> 0 | I33: Перенесено в нераспр.приб. | L33: =L29-L32 -> -103558 | O33: Акционерный капитал | R33: =W!A275 -> 3000000
C34: Безусловная франшиза | F34: =W!A220 -> 979 | I34: Нераспр. приб. в предпосл.кв. | L34: =W!A260 -> -247640 | O34: Счёт премий на акции | R34: =W!A276 -> 0 | U34: Лимит овердрафта на след.кв. | X34: =W!A238 -> 380000
I35: Нераспределенная прибыль | L35: =L33+L34 -> -351198 | O35: Нераспределённая прибыль | R35: =R36-R33-R34 -> -351198 | U35: Кредитоспособность | X35: =W!A239 -> 1025000
O36: Итого капитал | R36: =W!A277 -> 2648802
B38: The Global Management Challenge is a business simulation designed by Edit Systems Ltd. (www.edit515.co.uk) and organised by SDG S.A. (www.worldgmc.com) World Copyright © 2013 - EDIT 515 Ltd, UK and SDG - Simuladores e Modelos de Gestão, S.A. Адаптировано Президентской Академией (РАНХиГС) для использования в России и СНГ

Sheet Информация о группе
G1: Информация о группе стр. 1 | I1: Группа | J1: =W!$A1 -> 0 | K1: Год | L1: =W!$A4 -> 2025 | M1: Кв | N1: =W!$A5 -> 2
C4: ЭКОНОМИЧЕСКАЯ ИНФОРМАЦИЯ | G4: ЕАЭС | H4: АСЕАН | I4: Остальной мир
C5: Валовый внутренний продукт (ВВП) | G5: =W!A505 -> 3778 | H5: =W!A506 -> 3982 | I5: =W!A504 -> 59
C6: Уровень безработицы (в %) | G6: =W!A507/10 -> 7.1 | H6: =W!A508/10 -> 5.4
C7: Внешнеторговый баланс | G7: =W!A509 -> 1298 | H7: =W!A510 -> 2515
C9: Информация о следующем квартале:
C10: Годовая проц. ставка ЦБ на сл. кв. (в %) | G10: =W!A501/10 -> 2.5 | H10: =W!A502/10 -> 1 | I10: Курс ерз. к доллару (ерз./$) | L10: =W!A511/100 -> 0.75
C13: Цена строительства (ерз./кв.м.) | G13: =W!A518 -> 500
C15: Цена полуфабрикатов (ерз./шт.) | G15: Продукт 1 | H15: Продукт 2 | I15: Продукт 3
C16: от (без премиальных материалов) | G16: =INT(L10*G20/1000) + 60 -> 97 | H16: =INT(L10*2*G20/1000) + 75 -> 149 | I16: =INT(L10*3*G20/1000) + 120 -> 231
C17: до (100% премиальных материалов) | G17: =INT(L10*1.5*G20/1000) + 60 -> 115 | H17: =INT(L10*1.5*2*G20/1000) + 75 -> 186 | I17: =INT(L10*1.5*3*G20/1000) + 120 -> 287
G19: СПОТ | H19: 3 мес. | I19: 6 мес.
C20: Цена обычного сырья (долларов за 1000 шт.) | G20: =W!A515 -> 49661 | H20: =W!A516 -> 49414 | I20: =W!A517 -> 48662
C23: БИЗНЕС-АНАЛИТИКА: | F23: =W!A681 -> Малые предприятия могут получить преимущества перед своими более
F24: =W!A682 -> крупными конкурентами за счет более быстрого выполнения работ и
F25: =W!A683 -> совершенствования существующих продуктов.
F26: =W!A684
F27: =W!A685
F28: =W!A686
C32: БЕСПЛАТНАЯ ИНФОРМАЦИЯ | F32: Компания | G32: Компания | H32: Компания | I32: Компания | J32: Компания | K32: Компания | L32: Компания | M32: Компания
F33: =W!A521 -> 1 | G33: =W!A541 -> 2 | H33: =W!A561 -> 3 | I33: =W!A581 -> 4 | J33: =W!A601 -> 5 | K33: =W!A621 -> 6 | L33: =W!A641 -> 7 | M33: =W!A661 -> 8
C34: Фондовый рынок:
C35: Цена акций (в евразцентах) | F35: =W!A522/100 -> 93.66 | G35: =W!A542/100 -> 93.66 | H35: =W!A562/100 -> 93.66 | I35: =W!A582/100 -> 93.66 | J35: =W!A602/100 -> 93.66 | K35: =W!A622/100 -> 93.66 | L35: =W!A642/100 -> 93.66 | M35: =W!A662/100 -> 93.66
C36: Рыночная стоимость (ерз.) | F36: =W!A523 -> 2809800 | G36: =W!A543 -> 2809800 | H36: =W!A563 -> 2809800 | I36: =W!A583 -> 2809800 | J36: =W!A603 -> 2809800 | K36: =W!A623 -> 2809800 | L36: =W!A643 -> 2809800 | M36: =W!A663 -> 2809800
C38: Дивиденды (в %) | F38: =W!A524 -> 0 | G38: =W!A544 -> 0 | H38: =W!A564 -> 0 | I38: =W!A584 -> 0 | J38: =W!A604 -> 0 | K38: =W!A624 -> 0 | L38: =W!A644 -> 0 | M38: =W!A664 -> 0
C39: Инвест. привлекательность | F39: =W!A525 -> 2809800 | G39: =W!A545 -> 2809800 | H39: =W!A565 -> 2809800 | I39: =W!A585 -> 2809800 | J39: =W!A605 -> 2809800 | K39: =W!A625 -> 2809800 | L39: =W!A645 -> 2809800 | M39: =W!A665 -> 2809800
C41: Отчёт о деятельности конкурентов:
C42: Цены на продукцию (ерз.)
C43: Продукт 1: ЕАЭС | F43: =W!A526 -> 285 | G43: =W!A546 -> 285 | H43: =W!A566 -> 285 | I43: =W!A586 -> 285 | J43: =W!A606 -> 285 | K43: =W!A626 -> 285 | L43: =W!A646 -> 285 | M43: =W!A666 -> 285
D44: АСЕАН | F44: =W!A527 -> 0 | G44: =W!A547 -> 0 | H44: =W!A567 -> 0 | I44: =W!A587 -> 0 | J44: =W!A607 -> 0 | K44: =W!A627 -> 0 | L44: =W!A647 -> 0 | M44: =W!A667 -> 0
D45: Интернет | F45: =W!A528 -> 0 | G45: =W!A548 -> 0 | H45: =W!A568 -> 0 | I45: =W!A588 -> 0 | J45: =W!A608 -> 0 | K45: =W!A628 -> 0 | L45: =W!A648 -> 0 | M45: =W!A668 -> 0
C46: Продукт 2: ЕАЭС | F46: =W!A529 -> 450 | G46: =W!A549 -> 450 | H46: =W!A569 -> 450 | I46: =W!A589 -> 450 | J46: =W!A609 -> 450 | K46: =W!A629 -> 450 | L46: =W!A649 -> 450 | M46: =W!A669 -> 450
D47: АСЕАН | F47: =W!A530 -> 0 | G47: =W!A550 -> 0 | H47: =W!A570 -> 0 | I47: =W!A590 -> 0 | J47: =W!A610 -> 0 | K47: =W!A630 -> 0 | L47: =W!A650 -> 0 | M47: =W!A670 -> 0
D48: Интернет | F48: =W!A531 -> 0 | G48: =W!A551 -> 0 | H48: =W!A571 -> 0 | I48: =W!A591 -> 0 | J48: =W!A611 -> 0 | K48: =W!A631 -> 0 | L48: =W!A651 -> 0 | M48: =W!A671 -> 0
C49: Продукт 3: ЕАЭС | F49: =W!A532 -> 680 | G49: =W!A552 -> 680 | H49: =W!A572 -> 680 | I49: =W!A592 -> 680 | J49: =W!A612 -> 680 | K49: =W!A632 -> 680 | L49: =W!A652 -> 680 | M49: =W!A672 -> 680
D50: АСЕАН | F50: =W!A533 -> 0 | G50: =W!A553 -> 0 | H50: =W!A573 -> 0 | I50: =W!A593 -> 0 | J50: =W!A613 -> 0 | K50: =W!A633 -> 0 | L50: =W!A653 -> 0 | M50: =W!A673 -> 0
D51: Интернет | F51: =W!A534 -> 0 | G51: =W!A554 -> 0 | H51: =W!A574 -> 0 | I51: =W!A594 -> 0 | J51: =W!A614 -> 0 | K51: =W!A634 -> 0 | L51: =W!A654 -> 0 | M51: =W!A674 -> 0
C53: Производственный персонал | F53: =W!A535 -> 27 | G53: =W!A555 -> 27 | H53: =W!A575 -> 27 | I53: =W!A595 -> 27 | J53: =W!A615 -> 27 | K53: =W!A635 -> 27 | L53: =W!A655 -> 27 | M53: =W!A675 -> 27
C54: Зарплата сборщиков (ерзцент./час) | F54: =W!A536 -> 1000 | G54: =W!A556 -> 1000 | H54: =W!A576 -> 1000 | I54: =W!A596 -> 1000 | J54: =W!A616 -> 1000 | K54: =W!A636 -> 1000 | L54: =W!A656 -> 1000 | M54: =W!A676 -> 1000
C55: Кол-во агентов и дистриб. | F55: =W!A537 -> 2 | G55: =W!A557 -> 2 | H55: =W!A577 -> 2 | I55: =W!A597 -> 2 | J55: =W!A617 -> 2 | K55: =W!A637 -> 2 | L55: =W!A657 -> 2 | M55: =W!A677 -> 2
...

Sheet W
A1: 0
A2: 0
A3: 999
A4: 2025
A5: 2
A6: 26C1
A7: 15
A8: 0
A9: 0
A10: 0
A11: 10
A12: 0
A13: 0
A14: 10
A15: 0
A16: 0
A17: 10
A18: 0
... A64: 0
A65: 0 | B65: *
A66: 0
A67: 0
A68: 0 | B68: *
A69: 0
A70: 0
A71: 0
A72: 0
A73: 2
A74: 0
A75: 15
A76: 2
A77: 0
A78: 0
A79: 0
A80: 0
... A104: 90
A105: 1.85
A106: 1.53
A107: 1.53
A108: 750
...
