Workbook
Name _W201141: W!$A$1:$B$865
Name WHStest_6: W!#REF!

Sheet Your decisions
G2: Управленческий отчёт
B3: =W!A861 -> 153 | V3: Код: | W3: =W!A6 -> 26C1
B4: =W!A862 -> 1
B5: =W!A863 -> 20 | H5: Компания | L5: =W!$A2 -> 0 | N5: Группа | O5: =W!$A1 -> 0
B6: =W!A864 -> 1
C9: ПРОВЕРЬТЕ … | H9: Решения | O9: Год | P9: =W!$A4 -> 2026 | R9: Кв | S9: =W!$A5 -> 1
E12: Имидж | F12: Продукт | G12: 1 | H12: Продукт | I12: 2 | J12: Продукт | K12: 3 | P12: Через | T12: Вознагр. | W12: Комис.
C13: Реклама (тыс. ерз.): | M13: Агенты и дистрибьюторы: | P13: квартал | T13: (тыс. ерз.) | W13: %
D14: ЕАЭС | E14: =W!A7 -> 30 | F14: =W!A11 -> 30 | H14: =W!A14 -> 30 | J14: =W!A17 -> 30 | M14: Агенты в ЕАЭС | P14: =W!A61 -> 2 | Q14: =W!B61 -> 0 | T14: =W!A62 -> 13 | U14: =W!B62 -> 0 | W14: =W!A63 -> 13
D15: АСЕАН | E15: =W!A8 -> 30 | F15: =W!A12 -> 30 | H15: =W!A15 -> 30 | J15: =W!A18 -> 30 | M15: Дистрибьюторы в АСЕАН | P15: =W!A64 -> 3 | Q15: =W!B64 -> 0 | T15: =W!A65 -> 13 | U15: =W!B65 -> 0 | W15: =W!A66 -> 13
D16: Интернет | E16: =W!A9 -> 30 | F16: =W!A13 -> 30 | H16: =W!A16 -> 30 | J16: =W!A19 -> 30 | M16: Интернет-агент | T16: =W!A68 -> 11 | U16: =W!B68 -> 0 | W16: =W!A69 -> 11
C18: Цены (ерз.): | M18: Операционная деятельность:
D19: ЕАЭС | F19: =W!A21 -> 360 | G19: =W!B21 -> 0 | H19: =W!A24 -> 610 | I19: =W!B24 -> 0 | J19: =W!A27 -> 850 | K19: =W!B27 -> 0 | M19: Заказано сырья (тыс.шт.) | O19: СПОТ | P19: =W!A57 -> 0 | S19: 3 мес. | T19: =W!A58 -> 0 | V19: 6 мес. | W19: =W!A59 -> 0
D20: АСЕАН | F20: =W!A22 -> 360 | G20: =W!B22 -> 0 | H20: =W!A25 -> 610 | I20: =W!B25 -> 0 | J20: =W!A28 -> 850 | K20: =W!B28 -> 0 | M20: Время на ТО 1 станка (час) | P20: =W!A75 -> 25 | S20: Кол-во рабочих смен | W20: =W!A76 -> 2
D21: Интернет | F21: =W!A23 -> 340 | G21: =W!B23 -> 0 | H21: =W!A26 -> 520 | I21: =W!B26 -> 0 | J21: =W!A29 -> 740 | K21: =W!B29 -> 0 | M21: Кол-во Интернет-портов | P21: =W!A77 -> 10 | S21: Развитие сайта (тыс. ерз.) | W21: =W!A78 -> 30
C23: Количество произведённой и отгруженной продукции (шт.): | M23: Управление персоналом
C24: Агенты в ЕАЭС | F24: =W!A31 -> 700 | G24: =W!B31 -> 0 | H24: =W!A34 -> 400 | I24: =W!B34 -> 0 | J24: =W!A37 -> 220 | K24: =W!B37 -> 0 | M24: Сборщики: Нанять (+) / Увол. (-) | P24: =W!A81 -> 0 | Q24: =W!B81 -> 0 | S24: Повыш. Квалификации | W24: =W!A82 -> 0 | X24: =W!B82 -> 0
C25: Дистрибьюторы в АСЕАН | F25: =W!A32 -> 925 | G25: =W!B32 -> 0 | H25: =W!A35 -> 475 | I25: =W!B35 -> 0 | J25: =W!A38 -> 250 | K25: =W!B38 -> 0 | M25: Часовая зарплата сборщика | P25: =W!A83/100 -> 10 | Q25: =W!B83 -> 0
C26: Интернет-агент | F26: =W!A33 -> 1000 | G26: =W!B33 -> 0 | H26: =W!A36 -> 600 | I26: =W!B36 -> 0 | J26: =W!A39 -> 250 | K26: =W!B39 -> 0 | M26: Управленческий бюджет (тыс.ерз.) | P26: =W!A85 -> 115 | Q26: =W!B85 -> 0 | S26: Тренинги (дней) | W26: =W!A86 -> 0 | X26: =W!B86 -> 0
D27: (доставлен не полностью, если пометка *)
C28: Качество продукции: | M28: Финансы:
C29: Внедрить новые разработки (1;0) | F29: =W!A41 -> 0 | H29: =W!A42 -> 0 | J29: =W!A43 -> 0 | M29: Эмиссия/Выкуп акций | P29: =W!A91 -> 0 | Q29: =W!B91 -> 0 | S29: Дивиденды (в %) | W29: =W!A92 -> 0 | X29: =W!B92 -> 0
C30: Вложения в НИОКР (тыс.ерз.) | F30: =W!A44 -> 30 | H30: =W!A45 -> 30 | J30: =W!A46 -> 30 | M30: Срочные кредиты (тыс. ерз.) | P30: =W!A93 -> 0 | Q30: =W!B93 -> 0 | S30: Срочный депозит (т. ерз.) | W30: =W!A94 -> 0 | X30: =W!B94 -> 0
C31: Время сборки (минуты) | F31: =W!A47 -> 115 | H31: =W!A48 -> 165 | J31: =W!A49 -> 325 | M31: Покупка станков (шт.) | P31: =W!A73 -> 0 | Q31: =W!B73 -> 0 | S31: Продажа станков (шт.) | W31: =W!A74 -> 0 | X31: =W!B74 -> 0
C32: Премиальные материалы (%) | F32: =W!A51 -> 0 | G32: =W!B51 -> 0 | H32: =W!A52 -> 0 | I32: =W!B52 -> 0 | J32: =W!A53 -> 0 | K32: =W!B53 -> 0 | M32: Расширение цеха (кв. м.) | P32: =W!A72 -> 0 | Q32: =W!B72 -> 0 | S32: Страховой план | W32: =W!A99 -> 2
C34: Аутсорсинг: | M34: Информация:
C35: Заказанные полуфабрикаты (шт.) | F35: =W!A54 -> 0 | G35: =W!B54 -> 0 | H35: =W!A55 -> 0 | I35: =W!B55 -> 0 | J35: =W!A56 -> 0 | K35: =W!B56 -> 0 | M35: О долях рынка | P35: =W!A97 -> 0 | S35: О дея-ти конкурентов | W35: =W!A98 -> 1
C37: The Global Management Challenge is a business simulation designed by Edit Systems Ltd. (www.edit515.co.uk) and organised by SDG S.A. (www.worldgmc.com)
M38: World Copyright © 2013 - EDIT 515 Ltd, UK and SDG - Simuladores e Modelos de Gestão, S.A.

Sheet Resources and products
D1: Группа | E1: =W!A1 -> 0 | F1: Компания | H1: =W!A2 -> 0 | M1: Ресурсы и продукты | T1: Год | U1: =W!A4 -> 2026 | W1: Кв | X1: =W!A5 -> 1
C4: Использование материальных ресурсов | K4: Человеческие ресурсы: | S4: Движение товара: | U4: Продукт 1 | W4: Продукт 2 | Y4: Продукт 3
S5: Количество продукции:
C6: Пространство: | G6: Кв. м. | K6: Движение персонала: | N6: Сборщики | O6: Механики | S6: Запланировано | U6: =W!A108 -> 2625 | W6: =W!A109 -> 1475 | Y6: =W!A110 -> 720
C7: Земля в собственности | G7: =W!A281 -> 9000 | K7: На начало прош. квартала | N7: =W!A191 -> 26 | O7: =W!A192 -> 76 | S7: Произведено | U7: =W!A111 -> 2719 | W7: =W!A112 -> 1530 | Y7: =W!A113 -> 747
C8: Инфраструктурные объекты | G8: =0.2*G7 -> 1800 | K8: рекрутировано | N8: =W!A193 -> 0 | O8: =W!A194 -> 12 | S8: Брак | U8: =W!A114 -> 94 | W8: =W!A115 -> 55 | Y8: =W!A116 -> 27
C9: Располагаемая площадь | G9: =G7-G8-G10 -> 6300 | K9: Обучено | N9: =W!A82 -> 0 | S9: Потеряно/уничтожено | U9: =W!A117 -> 0 | V9: =W!B117 -> 0 | W9: =W!A118 -> 0 | X9: =W!B118 -> 0 | Y9: =W!A119 -> 0 | Z9: =W!B119 -> 0
C10: Размер цеха в след. квартале | G10: =W!A284 -> 900 | K10: Уволено | N10: =W!A195 -> 0 | O10: =W!A196 -> 0
C11: Инфраструктура цеха | G11: =0.25*G10 -> 225 | K11: Увол. по собств. желанию | N11: =N7+N8+N9-N10-N12 -> 0 | O11: =O7+O8+O9-O10-O12 -> 12 | S11: Отгружено:
C12: Изготовление деталей | G12: =W!A285 -> 275 | K12: Доступно на нач.след.кв. | N12: =W!A197 -> 26 | O12: =W!A198 -> 76 | S12: Агентам в ЕАЭС | U12: =W!A121 -> 700 | W12: =W!A124 -> 400 | Y12: =W!A127 -> 220
C13: Сборка | G13: =W!A286 -> 260 | S13: Дистрибьюторам АСЕАН | U13: =W!A122 -> 925 | W13: =W!A125 -> 475 | Y13: =W!A128 -> 250
C14: Складирование | G14: =W!A287 -> 0 | S14: Интернет-агенту | U14: =W!A123 -> 1000 | W14: =W!A126 -> 600 | Y14: =W!A129 -> 250
C15: Свободная площадь (+/-): | G15: =G10-SUM(G11:G14) -> 140 | K15: Сборщики: | O15: Часы
K16: Доступно часов работы в прош.кв | O16: =W!A305 -> 14976 | S16: Заказы из:
C17: Станки: | G17: Количество | K17: Общее время отсутствия/болезни | O17: =W!A306 -> 234 | P17: =W!B307 -> 0 | S17: ЕАЭС | U17: =W!A131 -> 707 | W17: =W!A134 -> 362 | Y17: =W!A137 -> 224
C18: Выведено из эксплуатации | G18: =W!A291 -> 0 | K18: Фактически отработано часов | O18: =W!A307 -> 13464 | S18: АСЕАН | U18: =W!A132 -> 889 | W18: =W!A135 -> 422 | Y18: =W!A138 -> 246
C19: Использовалось в прош. квартале | G19: =W!A292 -> 11 | O19: Недели | S19: Интернет | U19: =W!A133 -> 1004 | W19: =W!A136 -> 618 | Y19: =W!A139 -> 325
C20: Куплено и установлено | G20: =W!A293 -> 0 | K20: Уведомл. о забастовках в след.кв-ле | O20: =W!A308 -> 0
C21: Доступно для след. квартала | G21: =W!A294 -> 11 | S21: Продано в:
S22: ЕАЭС | U22: =W!A141 -> 700 | W22: =W!A144 -> 365 | Y22: =W!A147 -> 220
C23: Доступных часов работы в прош.кв. | G23: =W!A301 -> 11748 | S23: АСЕАН | U23: =W!A142 -> 925 | W23: =W!A145 -> 432 | Y23: =W!A148 -> 250
C24: Часов простоя станков | G24: =W!A302 -> 38 | H24: =W!B302 -> 0 | S24: Интернет | U24: =W!A143 -> 1000 | W24: =W!A146 -> 600 | Y24: =W!A149 -> 250
C25: Отработано часов в прош. кв. | G25: =W!A303 -> 6652 | K25: Движение агентов: | M25: ЕАЭС | N25: АСЕАН | O25: Интернет
C26: Часы запланированного техосмотра | G26: =G19*W!A75-G24 -> 237 | K26: Доступные в прош.кв. | M26: =W!A321 -> 2 | N26: =W!A322 -> 3 | O26: =IF(W!A327>0,1,0) -> 1 | S26: Долги по поставкам:
C27: Средняя эффективность станка % | G27: =W!A304 -> 92.1 | K27: Покинули компанию | M27: =W!A323 -> 0 | N27: =W!A324 -> 0 | S27: ЕАЭС | U27: =W!A151 -> 55 | W27: =W!A154 -> 0 | Y27: =W!A157 -> 11
K28: Уволены в прошл.кв. | M28: =MAX(M26-M27-M30,0) -> 0 | N28: =MAX(N26-N27-N30,0) -> 0 | O28: =O26-O30 -> 0 | S28: АСЕАН | U28: =W!A152 -> 17 | W28: =W!A155 -> 0 | Y28: =W!A158 -> 0
C29: Материалы: | K29: Нанятые для след.кв. | M29: =MAX(M30-M26+M27,0) -> 0 | N29: =MAX(N30-N26+N27,0) -> 0 | O29: =O30-O26 -> 0
C30: Остатки сырья на начало периода | G30: =W!A311 -> 3098 | K30: Доступно в след.кв. | M30: =W!A325 -> 2 | N30: =W!A326 -> 3 | O30: =IF(W!A328>0,1,0) -> 1 | S30: Склады:
C31: Закуплено сырья в прош. кв. | G31: =1000*W!A57+W!A312 -> 0 | S31: ЕАЭС | U31: =W!A161 -> 0 | W31: =W!A164 -> 35 | Y31: =W!A167 -> 0
C32: Закуплено автоматически | G32: =W!A313 -> 4922 | S32: АСЕАН | U32: =W!A162 -> 0 | W32: =W!A165 -> 43 | Y32: =W!A168 -> 0
C33: Потеряно/уничтожено | G33: =W!A314 -> 0 | H33: =W!B313 -> 0 | S33: Интернет | U33: =W!A163 -> 0 | W33: =W!A166 -> 0 | Y33: =W!A169 -> 0
C34: Использовано сырья | G34: =W!A315 -> 8020
C35: Остатки сырья на конец прош. кв. | G35: =W!A316 -> 0 | K35: Транспорт: | M35: ЕАЭС | N35: АСЕАН | O35: Интернет
C36: Будет доставлено в след. квартале: | K36: Сред.километраж | M36: =W!A295 -> 1434 | N36: =W!A297 -> 500 | O36: =W!A299 -> 300 | S36: Обслужено по | U36: =W!A171 -> 109 | V36: =W!B171 -> 0 | W36: =W!A172 -> 62 | X36: =W!B172 -> 0 | Y36: =W!A173 -> 33 | Z36: =W!B173 -> 0
C37: Купленного в прошлом квартале | G37: =1000*W!A58 -> 0 | K37: Кол-во отгрузок | M37: =W!A296 -> 5 | N37: =W!A298 -> 6 | O37: =W!A300 -> 7 | S37: гарантии
C38: Купленного 2 квартала назад | G38: =W!A317 -> 0
C39: Будет доставлено через один квартал: | G39: =1000*W!A59 -> 0 | S39: Новые разработки | U39: =W!A177 -> None | W39: =W!A178 -> None | Y39: =W!A179 -> Minor
C41: Интернет-статистика: | S41: Полуфабрикаты:
C42: Количество действующих портов | G42: =W!A318 -> 10 | K42: Углеродный след (CO2e): | N42: Тонны | S42: Использовано в сборке | U42: =W!A181 -> 0 | W42: =W!A182 -> 0 | Y42: =W!A183 -> 0
C43: Успешные посещения сайта | G43: =W!A319 -> 79590 | K43: Отопление и освещение цеха | N43: =0.00019*50*G10 -> 8.55 | S43: Заказано в прошл. кв. | U43: =W!A54 -> 0 | W43: =W!A55 -> 0 | Y43: =W!A56 -> 0
...

Sheet Financial statements
D1: Группа | E1: =W!A1 -> 0 | F1: Компания | I1: =W!A2 -> 0 | M1: Финансовая отчётность | U1: Год | V1: =W!A4 -> 2026 | W1: Кв | X1: =W!A5 -> 1
C4: ФИНАНСОВАЯ ОТЧЁТНОСТЬ | F4: (ерз. )
U5: ОТЧЁТ О ДВИЖЕНИИ
C6: НАКЛАДНЫЕ РАСХОДЫ | I6: ОТЧЁТ О ПРИБЫЛЯХ И УБЫТКАХ | O6: БАЛАНС КОМПАНИИ | U6: ДЕНЕЖНЫХ СРЕДСТВ
C8: Реклама | F8: =W!A201 -> 360000 | I8: Выручка от реализации | L8: =W!A241 -> 2319070 | O8: Внеоборотные активы: | U8: Операционная деятельность:
C9: Интернет-агент | F9: =W!A202 -> 103070 | O9: Стоимость земли | R9: =W!A261 -> 450000 | U9: Поступления от продаж | X9: =W!A221 -> 2391823
C10: Интернет-провайдер | F10: =W!A203 -> 35110 | I10: Складские ост. на начало кв. | L10: =W!A242 -> 99633 | O10: Стоимость построек | R10: =W!A262 -> 450000 | U10: Страховые поступления | X10: =W!A222 -> 0
C11: Агенты и дистрибьюторы | F11: =W!A204 -> 256717 | I11: Закупленные полуфабрикаты | L11: =W!A243 -> 0 | O11: Стоимость оборудования | R11: =W!A263 -> 2236530 | U11: Платежи по операц. деят-ти | X11: =W!A223 -> 1864405
C12: Офис продаж | F12: =W!A205 -> 23555 | I12: Закупленное сырье | L12: =W!A244 -> 233882 | O12: Всего внеоборотных активов | R12: =SUM(R9:R11) -> 3136530 | U12: Уплаченные налоги | X12: =W!A224 -> 0
C13: Гарантийное обслуживание | F13: =W!A206 -> 24090 | I13: Затраты на эксплуатацию станков | L13: =W!A245 -> 121536 | U13: Ден. поток по операц. деят-ти | X13: =X9+X10-X11-X12 -> 527418
C14: Исследования и разработки | F14: =W!A207 -> 90000 | I14: Зарплаты механиков | L14: =W!A246 -> 274560 | O14: Оборотные активы:
C15: Развитие веб-сайта | F15: =W!A208 -> 30000 | I15: Зарплаты сборщиков | L15: =W!A247 -> 149160 | O15: Ст-ть товарных запасов | R15: =W!A265 -> 12168 | U15: Инвестиционная деятельность:
C16: Отдел персонала | F16: =W!A209 -> 12000 | I16: Контроль качества | L16: =W!A248 -> 4996 | O16: Ст-ть запасов полуфабр. | R16: =W!A266 -> 0 | U16: Полученный процент | X16: =W!A225 -> 0
C17: Техобслуживание оборудов. | F17: =W!A210 -> 23375 | I17: Аренда транспорта | L17: =W!A249 -> 73350 | O17: Стоимость запасов сырья | R17: =W!A267 -> 0 | U17: Активов продано | X17: =W!A226 -> 0
C18: Складирование и закупка | F18: =W!A211 -> 7655 | I18: Складские ост. на конец кв. | L18: =W!A250 -> 12168 | O18: Дебиторская задолженность | R18: =W!A268 -> 1378455 | U18: Активов куплено | X18: =W!A227 -> 0
C19: Расходы на маркет.исслед. | F19: =W!A212 -> 7500 | I19: Затраты на пр-во и реал. пр. | L19: =W!A251 -> 944949 | O19: Денежные ср-ва и их экв-ты | R19: =W!A269 -> 1390772 | U19: Ден. поток по инвест. деят-ти | X19: =X16+X17-X18 -> 0
C20: Кредитный контроль | F20: =W!A213 -> 4742 | I20: Валовая прибыль/убыток | L20: =W!A252 -> 1374121 | O20: Итого оборотные активы | R20: =SUM(R15:R19) -> 2781395
C21: Страховая премия | F21: =W!A214 -> 11527 | I21: Накладные расходы | L21: =W!A217 -> 1123793 | O21: Итого активы | R21: =R12+R20 -> 5917925 | U21: Финансовая деятельность:
C22: Управленческий бюджет | F22: =W!A215 -> 115000 | I22: Страховые поступления | L22: =W!A222 -> 0 | U22: Акций выпущено | X22: =W!A228 -> 0
C23: Прочие издержки | F23: =W!A216 -> 19452 | I23: Амортизация | L23: =W!A254 -> 57349 | O23: Обязательства: | U23: Акций выкуплено | X23: =W!A229 -> 0
C24: Итого накладные расходы | F24: =W!A217 -> 1123793 | I24: Операц. прибыль/убыток | L24: =L20-L21+L22-L23 -> 192979 | O24: Задолженность по налогам | R24: =W!A271 -> 201231 | U24: Дивиденды | X24: =W!A230 -> 0
I25: Полученный процент | L25: =W!A225 -> 0 | O25: Кредиторская задолженность | R25: =W!A272 -> 635411 | U25: Доп. срочные кредиты | X25: =W!A231 -> 0
C26: Налогообл. прибыль/убыток (накопл.): | I26: Уплаченный процент | L26: =W!A232 -> 0 | O26: Банковский овердрафт | R26: =W!A273 -> 0 | U26: Уплаченный процент | X26: =W!A232 -> 0
C27: Прибыль до налогообложения | F27: =L27 -> 192979 | I27: Прибыль/убыток до налогообл. | L27: =L24+L25-L26 -> 192979 | O27: Краткосрочные обязательства | R27: =SUM(R24:R26) -> 836642 | U27: Ден. поток по фин. деят-ти | X27: =X22-X23-X24+X25-X26 -> 0
C28: Налогообл. приб. в прош. кв. | F28: =W!A240 -> 0 | I28: Налоги начисленные | L28: =W!A255 -> 0 | O28: Срочные кредиты | R28: =W!A274 -> 0
C29: Налогооблагаемая прибыль | F29: =W!A257 -> 192979 | I29: Прибыль за отчётный период | L29: =W!A256 -> 192979 | U29: Чистый денежный поток | X29: =W!A233 -> 527418
I30: Прибыль на акцию (ерзцент) | L30: =IF(R33>0,100*L29/R33,0) -> 4.824475 | O30: Чистые активы | R30: =R21-R27-R28 -> 5081283 | U30: Нал. ср-ва в позапрош. кв. | X30: =W!A234 -> 863354
U31: Наличные средства | X31: =R19-R26 -> 1390772
I32: Дивиденды | L32: =W!A230 -> 0 | O32: Собственный капитал: | U32: (включая срочный депозит - | X32: =W!A270 -> 0 | Y32: )
C33: Иски к страховой компании | F33: =W!A219 -> 600 | I33: Перенесено в нераспр.приб. | L33: =L29-L32 -> 192979 | O33: Акционерный капитал | R33: =W!A275 -> 4000000
C34: Безусловная франшиза | F34: =W!A220 -> 6587 | I34: Нераспр. приб. в предпосл.кв. | L34: =W!A260 -> 888304 | O34: Счёт премий на акции | R34: =W!A276 -> 0 | U34: Лимит овердрафта на след.кв. | X34: =W!A238 -> 860000
I35: Нераспределенная прибыль | L35: =L33+L34 -> 1081283 | O35: Нераспределённая прибыль | R35: =R36-R33-R34 -> 1081283 | U35: Кредитоспособность | X35: =W!A239 -> 1863000
O36: Итого капитал | R36: =W!A277 -> 5081283
B38: The Global Management Challenge is a business simulation designed by Edit Systems Ltd. (www.edit515.co.uk) and organised by SDG - Simuladores e Modelos de Gestão S.A. Portugal
M39: World Copyright © 2013 - EDIT 515 Ltd, UK and SDG - Simuladores e Modelos de Gestão, S.A.

Sheet Group information
G1: Информация о группе стр. 1 | I1: Группа | J1: =W!$A1 -> 0 | K1: Год | L1: =W!$A4 -> 2026 | M1: Кв | N1: =W!$A5 -> 1
C4: ЭКОНОМИЧАСЕАНКАЯ ИНФОРМАЦИЯ | G4: ЕАЭС | H4: АСЕАН | I4: Остальной мир
C5: Валовый внутренний продукт (ВВП) | G5: =W!A505 -> 3969 | H5: =W!A506 -> 5240 | I5: =W!A504 -> 5390
C6: Уровень безработицы (в %) | G6: =W!A507/10 -> 6.1 | H6: =W!A508/10 -> 9.3
C7: Внешнеторговый баланс | G7: =W!A509 -> 1570 | H7: =W!A510 -> -933
C9: Информация о следующем квартале:
C10: Годовая проц. ставка ЦБ на сл. кв. (в %) | G10: =W!A501/10 -> 1.5 | H10: =W!A502/10 -> 1 | I10: Курс ерз. к доллару (ерз./$) | L10: =W!A511/100 -> 1.14
C13: Цена строительства (ерз./кв.м.) | G13: =W!A518 -> 500
C15: Цена полуфабрикатов (ерз./шт.) | G15: Продукт 1 | H15: Продукт 2 | I15: Продукт 3
C16: от (без премиальных материалов) | G16: =INT(L10*G20/1000) + 60 -> 102 | H16: =INT(L10*2*G20/1000) + 75 -> 160 | I16: =INT(L10*3*G20/1000) + 120 -> 248
C17: до (100% премиальных материалов) | G17: =INT(L10*1.5*G20/1000) + 60 -> 124 | H17: =INT(L10*1.5*2*G20/1000) + 75 -> 203 | I17: =INT(L10*1.5*3*G20/1000) + 120 -> 313
G19: СПОТ | H19: 3 мес. | I19: 6 мес.
C20: Цена обычного сырья (долларов за 1000 шт.) | G20: =W!A515 -> 37705 | H20: =W!A516 -> 33777 | I20: =W!A517 -> 31208
C23: БИЗНЕС-АНАЛИТИКА: | F23: =W!A681 -> Долги в развитых странах сейчас выше, чем до финансового кризиса. Ожидается,
F24: =W!A682 -> что это приведет к росту мировых процентных ставок. Многие центральные банки
F25: =W!A683 -> удерживают процентные ставки на низком уровне. Как долго это может
F26: =W!A684 -> продолжаться и как это повлияет на мировую экономику,
F27: =W!A685 -> если процентные ставки внезапно вырастут?
F28: =W!A686
C32: БЕСПЛАТНАЯ ИНФОРМАЦИЯ | F32: Компания | G32: Компания | H32: Компания | I32: Компания | J32: Компания | K32: Компания | L32: Компания | M32: Компания
F33: =W!A521 -> 1 | G33: =W!A541 -> 2 | H33: =W!A561 -> 3 | I33: =W!A581 -> 4 | J33: =W!A601 -> 5 | K33: =W!A621 -> 6 | L33: =W!A641 -> 7 | M33: =W!A661 -> 8
C34: Фондовый рынок:
C35: Цена акций (в евразцентах) | F35: =W!A522/100 -> 136.13 | G35: =W!A542/100 -> 136.13 | H35: =W!A562/100 -> 136.13 | I35: =W!A582/100 -> 136.13 | J35: =W!A602/100 -> 136.13 | K35: =W!A622/100 -> 136.13 | L35: =W!A642/100 -> 136.13 | M35: =W!A662/100 -> 136.13
C36: Рыночная стоимость (ерз.) | F36: =W!A523 -> 5445200 | G36: =W!A543 -> 5445200 | H36: =W!A563 -> 5445200 | I36: =W!A583 -> 5445200 | J36: =W!A603 -> 5445200 | K36: =W!A623 -> 5445200 | L36: =W!A643 -> 5445200 | M36: =W!A663 -> 5445200
C38: Дивиденды (в %) | F38: =W!A524 -> 0 | G38: =W!A544 -> 0 | H38: =W!A564 -> 0 | I38: =W!A584 -> 0 | J38: =W!A604 -> 0 | K38: =W!A624 -> 0 | L38: =W!A644 -> 0 | M38: =W!A664 -> 0
C39: Инвест. привлекательность | F39: =W!A525 -> 5609444 | G39: =W!A545 -> 5609444 | H39: =W!A565 -> 5609444 | I39: =W!A585 -> 5609444 | J39: =W!A605 -> 5609444 | K39: =W!A625 -> 5609444 | L39: =W!A645 -> 5609444 | M39: =W!A665 -> 5609444
C41: Отчёт о деятельности конкурентов:
C42: Цены на продукцию (ерз.)
C43: Продукт 1: ЕАЭС | F43: =W!A526 -> 360 | G43: =W!A546 -> 360 | H43: =W!A566 -> 360 | I43: =W!A586 -> 360 | J43: =W!A606 -> 360 | K43: =W!A626 -> 360 | L43: =W!A646 -> 360 | M43: =W!A666 -> 360
D44: АСЕАН | F44: =W!A527 -> 360 | G44: =W!A547 -> 360 | H44: =W!A567 -> 360 | I44: =W!A587 -> 360 | J44: =W!A607 -> 360 | K44: =W!A627 -> 360 | L44: =W!A647 -> 360 | M44: =W!A667 -> 360
D45: Интернет | F45: =W!A528 -> 340 | G45: =W!A548 -> 340 | H45: =W!A568 -> 340 | I45: =W!A588 -> 340 | J45: =W!A608 -> 340 | K45: =W!A628 -> 340 | L45: =W!A648 -> 340 | M45: =W!A668 -> 340
C46: Продукт 2: ЕАЭС | F46: =W!A529 -> 610 | G46: =W!A549 -> 610 | H46: =W!A569 -> 610 | I46: =W!A589 -> 610 | J46: =W!A609 -> 610 | K46: =W!A629 -> 610 | L46: =W!A649 -> 610 | M46: =W!A669 -> 610
D47: АСЕАН | F47: =W!A530 -> 610 | G47: =W!A550 -> 610 | H47: =W!A570 -> 610 | I47: =W!A590 -> 610 | J47: =W!A610 -> 610 | K47: =W!A630 -> 610 | L47: =W!A650 -> 610 | M47: =W!A670 -> 610
D48: Интернет | F48: =W!A531 -> 520 | G48: =W!A551 -> 520 | H48: =W!A571 -> 520 | I48: =W!A591 -> 520 | J48: =W!A611 -> 520 | K48: =W!A631 -> 520 | L48: =W!A651 -> 520 | M48: =W!A671 -> 520
C49: Продукт 3: ЕАЭС | F49: =W!A532 -> 850 | G49: =W!A552 -> 850 | H49: =W!A572 -> 850 | I49: =W!A592 -> 850 | J49: =W!A612 -> 850 | K49: =W!A632 -> 850 | L49: =W!A652 -> 850 | M49: =W!A672 -> 850
D50: АСЕАН | F50: =W!A533 -> 850 | G50: =W!A553 -> 850 | H50: =W!A573 -> 850 | I50: =W!A593 -> 850 | J50: =W!A613 -> 850 | K50: =W!A633 -> 850 | L50: =W!A653 -> 850 | M50: =W!A673 -> 850
D51: Интернет | F51: =W!A534 -> 740 | G51: =W!A554 -> 740 | H51: =W!A574 -> 740 | I51: =W!A594 -> 740 | J51: =W!A614 -> 740 | K51: =W!A634 -> 740 | L51: =W!A654 -> 740 | M51: =W!A674 -> 740
C53: Производственный персонал | F53: =W!A535 -> 114 | G53: =W!A555 -> 114 | H53: =W!A575 -> 114 | I53: =W!A595 -> 114 | J53: =W!A615 -> 114 | K53: =W!A635 -> 114 | L53: =W!A655 -> 114 | M53: =W!A675 -> 114
C54: Зарплата сборщиков (ерзцент./час) | F54: =W!A536 -> 1000 | G54: =W!A556 -> 1000 | H54: =W!A576 -> 1000 | I54: =W!A596 -> 1000 | J54: =W!A616 -> 1000 | K54: =W!A636 -> 1000 | L54: =W!A656 -> 1000 | M54: =W!A676 -> 1000
C55: Кол-во агентов и дистриб. | F55: =W!A537 -> 5 | G55: =W!A557 -> 5 | H55: =W!A577 -> 5 | I55: =W!A597 -> 5 | J55: =W!A617 -> 5 | K55: =W!A637 -> 5 | L55: =W!A657 -> 5 | M55: =W!A677 -> 5
...

Sheet W
A1: 0
A2: 0 | B2: #
A3: 999
A4: 2026
A5: 1
A6: 26C1
A7: 30
A8: 30
A9: 30
A10: 0
A11: 30
A12: 30
A13: 30
A14: 30
A15: 30
A16: 30
A17: 30
A18: 30
... A104: 138
A105: 3.95
A106: 4.33
A107: 3.93
A108: 2625
A109: 1475
A110: 720
A111: 2719
A112: 1530
A113: 747
A114: 94
A115: 55
A116: 27
A117: 0
A118: 0
A119: 0
... A176: 999
A177: None
A178: None
A179: Minor
A180: 999
A181: 0
...
